Workbook

Sheet JORDAN
A1: JORDAN
B2: DOSSIER : | C2: DATE RAJOUT | D2: DDL. 1ERE REPONSE | E2: COM. | F2: DDL. COM. | G2: STATUT | H2: COMMENTAIRES : | I2: DOSSIER TERMINÉ :
A3: J | B3: Plaquette - Centre Service | C3: 45995.524 | D3: =IFERROR(_xlfn.WORKDAY.INTL(C3, 2),"-") -> 45999 | E3: - | G3: ! Urgent ! | I3: FAUX
A4: J | B4: Destia La Mure | C4: 46001.37 | D4: =IFERROR(_xlfn.WORKDAY.INTL(C4, 2),"-") -> 46003 | E4: - | G4: Attente R. | H4: BAT VT + BAT V1 envoyé le 19/12 | I4: FAUX
A5: J | B5: GDS Niort | C5: 46006.663 | D5: =IFERROR(_xlfn.WORKDAY.INTL(C5, 2),"-") -> 46008 | E5: - | G5: A faire | I5: FAUX
A6: J | B6: Temporis Cannes | C6: 46006.663 | D6: =IFERROR(_xlfn.WORKDAY.INTL(C6, 2),"-") -> 46008 | E6: - | G6: A faire | I6: FAUX
A7: J | B7: Centre Services - Saint Brieuc | C7: 46003.406 | D7: =IFERROR(_xlfn.WORKDAY.INTL(C7, 2),"-") -> 46007 | E7: - | G7: Mairie | H7: BAT V1 franchiseur envoyé le 17/12 - Dossier mairie le 17/12 | I7: FAUX
A8: J | B8: Camif Habiat - Crapone | C8: 46007.442 | D8: =IFERROR(_xlfn.WORKDAY.INTL(C8, 2),"-") -> 46009 | E8: - | G8: Attente R. | H8: BAT V1 + BAT VT + Adhésif provisoire fait le 16/12 - BAT V2 franchiseur le 19/12 - Ok franchiseur - BAT Franchisé le 22/12 | I8: FAUX
A9: J | B9: EDRA - Bertelli et Fils | C9: 46003.406 | D9: =IFERROR(_xlfn.WORKDAY.INTL(C9, 2),"-") -> 46007 | E9: - | G9: Attente R. | H9: BAT V1 envoyé le 15/12 - V2 le 22/12 | I9: FAUX
A10: J | B10: Destia - Nogent sur Marne | C10: 45995.512 | D10: =IFERROR(_xlfn.WORKDAY.INTL(C10, 2),"-") -> 45999 | E10: - | G10: Attente R. | H10: BAT VT + BAT V1 envoyé le 15/12 | I10: FAUX
A11: J | B11: Destia - Vincennes | C11: 45995.512 | D11: =IFERROR(_xlfn.WORKDAY.INTL(C11, 2),"-") -> 45999 | E11: - | G11: Attente R. | H11: BAT V1 + BAT VT envoyé le 12/12 | I11: FAUX
A12: J | B12: Temporis Orly | C12: 46000.451 | D12: =IFERROR(_xlfn.WORKDAY.INTL(C12, 2),"-") -> 46002 | E12: - | G12: Attente R. | H12: BAT VT + BAT V1 envoyé le 10/12 - BAT V2 le 16/12 - BAT Validé, mais attente de visite technique pour FAB | I12: FAUX
A13: J | B13: Destia - Ajaccio | C13: 45973.367 | D13: =IFERROR(_xlfn.WORKDAY.INTL(C13, 2),"-") -> 45975 | E13: - | G13: Attente R. | H13: BAT VT + BAT V1 envoyé le 18/11 - V2 le 09/12 - V3 le 18/12 | I13: FAUX
A14: J | B14: Destia - Lys | C14: 45978.352 | D14: =IFERROR(_xlfn.WORKDAY.INTL(C14, 2),"-") -> 45980 | E14: - | G14: Attente R. | H14: BAT V1 envoyé le 25/11 - V2 envoyé le 03/12 - V3 le 04/12 - Passage du dossier en mairie côté client - BAT Mairie préparé | I14: FAUX
A15: J | B15: GDS - Lyon Sud Ouest | C15: 45939.677 | D15: =IFERROR(_xlfn.WORKDAY.INTL(C15, 2),"-") -> 45943 | E15: - | G15: Attente R. | H15: ta | I15: FAUX
A16: J | B16: EDRA Touques Carrosserie Cuvilliez | C16: 45987.624 | D16: =IFERROR(_xlfn.WORKDAY.INTL(C16, 2),"-") -> 45989 | E16: - | G16: Attente R. | H16: BAT V1 envoyé le 08/12 - V2 le 09/12 | I16: FAUX
A17: J | B17: Temporis - Marseille La Joliette | C17: 45992.639 | D17: =IFERROR(_xlfn.WORKDAY.INTL(C17, 2),"-") -> 45994 | E17: - | G17: Attente R. | H17: BAT V1 envoyé le 01/12 - V2 le 05/12 | I17: FAUX
A18: J | B18: EDRA - Garage DMC | C18: 45987.624 | D18: =IFERROR(_xlfn.WORKDAY.INTL(C18, 2),"-") -> 45989 | E18: - | G18: Attente R. | H18: BAT V1 envoyé le 01/12 | I18: FAUX
... A42: J | B42: MBB Levallois | C42: 45369.346 | D42: =IFERROR(_xlfn.WORKDAY.INTL(C42, 2),"-") -> 45371 | E42: F | G42: Stand-by | H42: REPRISE DOSSIER LAURIE : MAQUETTE ENVOYE LE 11/01 - maquette 2 le 22/01 - toujours en attente le 26/02 demandé à florent le 07/03 pas de news - Relance Flo le 15/05 - Attente cet été pour ce projet - Relance le 16/10 - Attente retour mairie | I42: FAUX
A43: J | B43: Novi - Vichy | C43: 45960.487 | D43: =IFERROR(_xlfn.WORKDAY.INTL(C43, 2),"-") -> 45964 | E43: M | G43: Stand-by | I43: FAUX
A44: J | C44: - | D44: =IFERROR(_xlfn.WORKDAY.INTL(C44, 2),"-") -> - | E44: - | I44: FAUX
A45: J | C45: - | D45: =IFERROR(_xlfn.WORKDAY.INTL(C45, 2),"-") -> - | E45: - | I45: FAUX
A46: J | C46: - | D46: =IFERROR(_xlfn.WORKDAY.INTL(C46, 2),"-") -> - | E46: - | I46: FAUX
A47: J | C47: - | D47: =IFERROR(_xlfn.WORKDAY.INTL(C47, 2),"-") -> - | E47: - | I47: FAUX
A48: J | C48: - | D48: =IFERROR(_xlfn.WORKDAY.INTL(C48, 2),"-") -> - | E48: - | I48: FAUX
A49: J | C49: - | D49: =IFERROR(_xlfn.WORKDAY.INTL(C49, 2),"-") -> - | E49: - | I49: FAUX
A50: J | C50: - | D50: =IFERROR(_xlfn.WORKDAY.INTL(C50, 2),"-") -> - | E50: - | I50: FAUX
A51: J | C51: - | D51: =IFERROR(_xlfn.WORKDAY.INTL(C51, 2),"-") -> - | E51: - | I51: FAUX
A52: J | C52: - | D52: =IFERROR(_xlfn.WORKDAY.INTL(C52, 2),"-") -> - | E52: - | I52: FAUX
A53: J | C53: - | D53: =IFERROR(_xlfn.WORKDAY.INTL(C53, 2),"-") -> - | E53: - | I53: FAUX
A54: J | C54: - | D54: =IFERROR(_xlfn.WORKDAY.INTL(C54, 2),"-") -> - | E54: - | I54: FAUX
A55: J | C55: - | D55: =IFERROR(_xlfn.WORKDAY.INTL(C55, 2),"-") -> - | E55: - | I55: FAUX
... A361: J | C361: - | D361: =IFERROR(_xlfn.WORKDAY.INTL(C361, 2),"-") -> - | E361: - | I361: FAUX

Sheet CAROLE
A1: CAROLE
B2: DOSSIER : | C2: DATE RAJOUT | D2: DDL. 1ERE REPONSE | E2: COM. | F2: DDL. COM. | G2: STATUT | H2: COMMENTAIRES : | I2: DOSSIER TERMINÉ :
A3: C | B3: Les lunettes de tipo | C3: 46007.626 | G3: A faire | I3: FAUX
A4: C | B4: Cassy pâtisserie | C4: 46007.722 | G4: A faire | I4: FAUX
A5: C | B5: Viva Services Beziers | C5: 46010.475 | G5: A faire | I5: FAUX
A6: C | B6: SQ Lyon Croix Rousse exterieur | C6: 45883.422 | G6: A faire | H6: BAT 1 envoyé BAT 2 envoyé BAT 3 envoyé BAT 4 envoyé BAT 5 envoyé BAT 6 envoyé BAT mairie fait le 16-10 --refus mairie | I6: FAUX
A7: C | B7: Euronet plaque | C7: 46009.483 | G7: Attente R. | H7: BAT 1 envoyé le 22-12 | I7: FAUX
A8: C | B8: SQ CDF Jean Richard exterieur | C8: 45883.394 | G8: Attente R. | H8: BAT VT fait le 18-08 BAT 1 envoyé le 22-08 Relance le 28-08 BAT 2 envoyé le 2-09 Dossier mairie à la charge du client - en attente de vaidation de sa part Finalement c'est nous qui faisons le dossier mairie > BAT mairie fait le 29-09 Nouveau BAt mairie fait le 1-12 -- Refus mairie BAT renvoyé à Paul en attente de validation pour renvoie en mairie (BAT mairie prêt) | I8: FAUX
A9: C | B9: SQ Bruz | C9: 46008.702 | G9: Attente R. | H9: BAT 1 envoyé le 17-12 | I9: FAUX
A10: C | B10: RIA FR15933 | C10: 46008.62 | G10: Attente R. | H10: BAT 1 envoyé le 17-12 BAT validé- attente VT et validation devis | I10: FAUX
A11: C | B11: Les lunettes de tipo adh noel | C11: 46008.367 | G11: Attente R. | H11: BAT 1 envoyé le 17-12 BAT 2 envoyé le 18-12 BAT 3 envoyé le 22-12 | I11: FAUX
A12: C | B12: SQ Saulce | C12: 46007.625 | G12: Attente R. | H12: BAT 1 envoyé le 16-12 Paul a mis en syand by le visuel | I12: FAUX
A13: C | B13: Sequoia pressing | C13: 46003.477 | G13: Attente R. | H13: Demande photo pour BAT VT envoyé le 16-12 | I13: FAUX
A14: C | B14: Inrae | C14: 46000.35 | G14: Attente R. | H14: STAND BY - recontacter en Janvier | I14: FAUX
A15: C | B15: SQ Sathonay | C15: 46001.763 | G15: Attente R. | H15: BAT 1 envoyé le 15-12 | I15: FAUX
A16: C | B16: RIA FR17384 | C16: 46001.763 | G16: Attente R. | H16: BAT 1 envoyé le 11-12 BAT 2 envoyé le 15-12 BAT 3 envoyé le 16-12 BAT validé- attente VT et validation devis | I16: FAUX
A17: C | B17: RIA FR17204 | C17: 46001.763 | G17: Attente R. | H17: BAT 1 envoyé le 11-12 BAT 2 envoyé le 18-12 BAT validé- attente VT et validation devis | I17: FAUX
... A62: C | B62: SQ Chatenay Malabry exterieur | C62: 45810.67 | G62: Mairie | H62: BAT VT fait le 17-03 VT incomplete, demande complément le 14-04 BAT 1 envoyé le 14-05 Relance le 14-05 BAT mairie fait le 3-06 Refus mairie - nouveua BAT transmis le 29-07 > en attente de validation pour renvoie en mairie BAT mairie fait le 29-07 Refus mairie BAT mairie renvoyé le 28-08 | I62: FAUX
A63: C | I63: FAUX
A64: C | I64: FAUX
A65: C | I65: FAUX
A66: C | I66: FAUX
A67: C | I67: FAUX
A68: C | I68: FAUX
A69: C | I69: FAUX
A70: C | I70: FAUX
A71: C | I71: FAUX
A72: C | I72: FAUX
A73: C | I73: FAUX
A74: C | I74: FAUX
... A518: C | I518: FAUX

Sheet HUGO
B2: DOSSIER : | C2: DATE RAJOUT | D2: DDL. 1ERE REPONSE | E2: COM. | F2: DDL. COM. | G2: STATUT | H2: COMMENTAIRES : | I2: DOSSIER TERMINÉ :
A3: H | C3: - | D3: =IFERROR(_xlfn.WORKDAY.INTL(C3, 2),"-") -> - | E3: - | I3: FAUX
A4: H | C4: - | D4: =IFERROR(_xlfn.WORKDAY.INTL(C4, 2),"-") -> - | E4: - | I4: FAUX
A5: H | C5: - | D5: =IFERROR(_xlfn.WORKDAY.INTL(C5, 2),"-") -> - | E5: - | I5: FAUX
A6: H | C6: - | D6: =IFERROR(_xlfn.WORKDAY.INTL(C6, 2),"-") -> - | E6: - | I6: FAUX
A7: H | C7: - | D7: =IFERROR(_xlfn.WORKDAY.INTL(C7, 2),"-") -> - | E7: - | I7: FAUX
A8: H | C8: - | D8: =IFERROR(_xlfn.WORKDAY.INTL(C8, 2),"-") -> - | E8: - | I8: FAUX
A9: H | C9: - | D9: =IFERROR(_xlfn.WORKDAY.INTL(C9, 2),"-") -> - | E9: - | I9: FAUX
A10: H | C10: - | D10: =IFERROR(_xlfn.WORKDAY.INTL(C10, 2),"-") -> - | E10: - | I10: FAUX
A11: H | C11: - | D11: =IFERROR(_xlfn.WORKDAY.INTL(C11, 2),"-") -> - | E11: - | I11: FAUX
A12: H | C12: - | D12: =IFERROR(_xlfn.WORKDAY.INTL(C12, 2),"-") -> - | E12: - | I12: FAUX
A13: H | C13: - | D13: =IFERROR(_xlfn.WORKDAY.INTL(C13, 2),"-") -> - | E13: - | I13: FAUX
A14: H | C14: - | D14: =IFERROR(_xlfn.WORKDAY.INTL(C14, 2),"-") -> - | E14: - | I14: FAUX
... A138: H | C138: - | D138: =IFERROR(_xlfn.WORKDAY.INTL(C138, 2),"-") -> - | E138: - | I138: FAUX
A139: H
A140: H | I140: FAUX
A141: H | I141: FAUX
A142: H | I142: FAUX
A143: H | I143: FAUX
A144: H | I144: FAUX
A145: H | I145: FAUX
A146: H | I146: FAUX
A147: H | I147: FAUX
A148: H | I148: FAUX
A149: H | I149: FAUX
A150: H | I150: FAUX
A151: H | I151: FAUX
... A1139: H | I1139: FAUX

Sheet AUDREY
A1: AUDREY
B2: DOSSIER : | C2: DATE RAJOUT | D2: DDL. 1ERE REPONSE | E2: COM. | F2: DDL. COM. | G2: STATUT | H2: COMMENTAIRES : | I2: DOSSIER TERMINÉ :
A3: A | B3: Fiches produit | C3: 45573.471 | G3: A faire | I3: FAUX
A4: A | B4: Lobby Guys Voiron | C4: 45636.72 | G4: A faire | I4: FAUX
A5: A | B5: Lobby Guys adhésifs machine | C5: 45637.627 | G5: Attente R. | H5: 19/12 BAT envoyé | I5: FAUX
A6: A | B6: [EDRA S.A] 69_CALUIRE ET CUIRE_DICK AUTO remplace la CO2410-2779 (reprendre l'historique) | C6: 45639.488 | G6: Attente R. | H6: 17/12 BAT envoyé | I6: FAUX
A7: A | B7: ROMEROLAND | C7: 45526.72 | E7: A | G7: Attente R. | H7: Projet lancé OK Adhésifs horaires à faire et expédier quand le client connaitra ses horaires d'ouverture 01/10 relance mail pour adhésif | I7: FAUX
A8: A | B8: EDRA S.A - 42_SAINT PRIEST EN JAREZ_CARROSSERIE FAYOLLE | C8: 45637.576 | E8: S | G8: Attente R. | H8: Pb en 2 parties > attente devis en 1 partie pour renvoyer le BAT | I8: FAUX
A9: A | B9: [EDRA S.A] 95_OSNY_CARROSSERIE JAMES - BAT mairie | C9: 45643.435 | E9: S | G9: Mairie | I9: FAUX
A10: A | B10: LES COCOTTES ROUSSES | C10: 45636.58 | G10: En cours | H10: COMMANDE TOILE nouveau format 10/12 demande de devis 11/12 Commande lancée chez SUn & Lux | I10: FAUX
A11: A | B11: EDRA S.A - 78_COIGNIERES_PRO AUTO | C11: 45637.576 | G11: En cours | H11: Refab a venir > attente validation client du devis de Sophie. Si il est validé telquel, j'ai préparé, sur le serveur et sur les tâches FP : - le nouveau BAT a envoyer - Le BAT pour la fab avec des indications pour la pose - Les fichiers de FAB | I11: FAUX
A12: A | B12: EDRA S.A - 77_ST THIBAULT DES VIGNES_OLYMPIC GARAGE | C12: 45637.578 | G12: En cours | H12: Commande ST en cours puis fichier de fab | I12: FAUX
A13: A | B13: EDRA S.A - 91_MENNECY_GARAGE CHRISTOPHE GENET | C13: 45637.576 | E13: S | G13: Mairie | H13: 08/11 envoi BAT ensuite BAT mairie | I13: FAUX
A14: A | B14: [EDRA S.A] 38_BOURGOIN JALLIEU_BELLET AUTOMOBILES | C14: 45600.637 | E14: S | G14: Mairie | I14: FAUX
A15: A | B15: [Boulangerie Thévenet] TOTEM panneau | C15: 45481.674 | E15: S | G15: Stand-by | H15: 09/07 Appeler client, la cliente amis un stand-by par mail le 09/07 21/10 relance mail | I15: FAUX
A16: A | I16: FAUX
A17: A | I17: FAUX
A18: A | I18: FAUX
A19: A | B19: CO2410-2843_1 - EDRA S.A - EDRA S.A - 71_MACON_CARROSSERIE DARNAND - REFAB PANNEAUX | H19: Refab avec bonnes dimensions / attente devis | I19: FAUX
A20: A | B20: CO2410-2895_1 - EDRA S.A - AXIAL COIGNIERES - REFAB PANNEAUX 2 ET 3 | H20: Refab avec bonnes dimensions / attente devis Fichiers pret si devis validé sans changement | I20: FAUX
A21: A | I21: FAUX
A22: A | I22: FAUX
A23: A | I23: FAUX
A24: A | I24: FAUX
A25: A | I25: FAUX
A26: A | I26: FAUX
A27: A | I27: FAUX
A28: A | I28: FAUX
A29: A | I29: FAUX
A30: A | I30: FAUX
A31: A | I31: FAUX
A32: A | I32: FAUX
... A756: A | I756: FAUX

Sheet JULIETTE
A1: JULIETTE
B2: DOSSIER : | C2: DATE RAJOUT | D2: DDL. 1ERE REPONSE | E2: COM. | F2: DDL. COM. | G2: STATUT | H2: COMMENTAIRES : | I2: DOSSIER TERMINÉ :
A3: JU | B3: SAS 2 big 1 Flyer professionnel | C3: 45985.601 | G3: A faire | H3: à commencer (on a déjà fait 2 flyer R/V il en reste à faire et à commander en 1000 exempalires - à confirmer avec le client) | I3: FAUX
A4: JU | B4: CO2510-4363_1 - RENOVERT - VALLET | C4: 45985.612 | G4: A faire | H4: BAT V1 - 15/10 BAT V2 - 15/10 BAT V3 - 16/10 BAT V4 - 22/10 BAT validé le 8/12 BAT à modifié suivant retour par mail
A5: JU | B5: CMD Lyon enseigne | C5: 45999.518 | G5: A faire | H5: BAT le 8/12 Retour le 17/12 (d'autres retour entres temps par mail) BAT à faire | I5: FAUX
A6: JU | B6: Urbencea | C6: 45999.518 | G6: A faire | H6: BAT v1 envoyé le 17/12 BAT v2 envoyé le 17/12 BAT v3 à faire | I6: FAUX
A7: JU | B7: GUY HOQUET Nation | C7: 45701.43 | D7: =IFERROR(_xlfn.WORKDAY.INTL(C7, 2),"-") -> 45705 | E7: - | G7: À relancer | H7: le franchisé est en cours de négociation avec le syndic de l'immeuble, à relancer à la fin du mois relance le 23/006 relanceer le 20/08 Relancer le 8/09 par tel et whatsapp Rien à faire mais ça serait cool de le relancer | I7: FAUX
A8: JU | B8: GUY HOQUET Chartes | C8: 45701.425 | D8: =IFERROR(_xlfn.WORKDAY.INTL(C8, 2),"-") -> 45705 | E8: - | G8: À relancer | H8: Bloquer car devis pas payer BAT v2 le 16/07 BAT envoyé le 3/09 au franchisé, en attente de sa validation Rien à faire mais ça serait cool de le relancer | I8: FAUX
A9: JU | B9: Novi - Annecy Sommeiller | C9: 45540.509 | D9: =IFERROR(_xlfn.WORKDAY.INTL(C9, 2),"-") -> 45544 | E9: - | G9: À relancer | H9: BAT VT envoyé le 22/07 BAT V1 envoyé le 7/10 BAT v2 envoyé le 21/10 Rien à faire relancé la franchisé pour la siganture de son BAT | I9: FAUX
A10: JU | B10: Bureau vallée L'isle adam | C10: 45811.362 | G10: À relancer | H10: BAT le 3/06 relance le 23/06 Client transmet à la centrale le 30/06 relance le 20/08 par mail Rien à faire - relance à faire | I10: FAUX
A11: JU | B11: Viva service Chambéry | C11: 45754.384 | G11: À relancer | H11: BAT VT le 2/04 BAT le 3/04 chez franchise BAT franchisé le 4/04 attente validation BAT mairie le 10/04 BAT renvoyé le 29/08 suite retour mairie Rien à faire - Sara le relance en parallèle Relance possible | I11: FAUX
A12: JU | B12: HD Audition | G12: À relancer | H12: BAT le 25/09 BAT v2 envoyé le 1/10 à relancer | I12: FAUX
A13: JU | B13: TC REtails | C13: 45985.605 | G13: À relancer | H13: BAT envoyé le 13/11 à relancer | I13: FAUX
A14: JU | B14: Gacem studio | C14: 45985.646 | G14: À relancer | H14: BAT envoyé le 4/09 à relancer | I14: FAUX
A15: JU | B15: Novi - Aix les Bains | C15: 45561.695 | D15: =IFERROR(_xlfn.WORKDAY.INTL(C15, 2),"-") -> 45565 | E15: - | G15: Attente R. | H15: BAT VT envoyé le 18/07 BAT v1 envoye lé 01/10 BAT le 27/05 Voir avec morgane les dimensions qui ont été prises Bat fait avec retours mairie (infos demandé à Marion G) Envoyé le 26/09 BAT mairie à faire en ajoutant un drapeau non lumineux fait le 24/11 le 2/12 > réception d'un nouveau retour mairie par Marion Gay > 1,regarder les prescritpion 2. Modifier maquette en suivant 3, Modifier maquette en tenant compte des ajouts demandées par Marie-Odile en parallèle 4, faire validé le tout à Marie-Odile 5, demander un nouveau devis à Michael OK ALORS VOILA Où ON EN EST : Le dernier BAT en date est presque validé Les retour mairie sont bien pris en compte Le dernier point pas validé, c'est que le franchisé (M,Bergerat) veut que son enseigne principale (N1 - N2) soit lumineuse Mais techniquement pas possible avec un panneau + des lettres il faudrait un caisson (mais caisson refusé par la mairie) Donc pas le choix que de faire une rampe lumineuse (vu avec Léa), je lui ai envoyé par mail cette proposition 'le 17/12/2025) Attente de son retour et il faudra refaire devisé à Michael et qu'il vérifie bien que tout ce qu'il y a au BAT est bien dans le devis | I15: FAUX
A16: JU | B16: BCR ASSET MANAGEMENT | C16: 45985.594 | G16: Attente R. | H16: BAT VT Et BAT fait le 4/12 BAT validé par Maureen le 9/12 attente VT pour envoyé le BAT à franchisé VT le 16/12 BAT franchisé le 17/12 Attente retour - rien à faire | I16: FAUX
A17: JU | B17: Guy Hoquet Chelles | C17: 45831.474 | G17: Attente R. | H17: BAT v1 envoyé le 3/07 BAT v2 envoyé le 8/07 BAT franchisé envoyé le 8/07 Relance par mail le 20/08 Demande d'ajout d'un panneau sous l'enseigne principale BAT envoyé le 12/12 et retour dans la journée demande à avoir aussi la partie verticale avec un panneau mais pas compris dans le devis Je lui ai fait un mail le 17/12 pour lui dire que c'ets pas compris dans le prix et qu'une mise en peinture serait mieux Attente de retour de sa part + lui redemander les cotes des deux boitiers en haut et gauche de chaque coté qui vont géné le panneau Attente retour rien à faire | I17: FAUX
A18: JU | B18: Novi - Bischheim | C18: 45540.513 | D18: =IFERROR(_xlfn.WORKDAY.INTL(C18, 2),"-") -> 45544 | E18: - | G18: Attente R. | H18: BAT VT envoyé le 11/07 BAT v1 envoyé le 19/09 BAT v2 envoyé le 21/10 Rien à faire | I18: FAUX
A19: JU | B19: Novi - St Julien en Genevois | C19: 45540.509 | D19: =IFERROR(_xlfn.WORKDAY.INTL(C19, 2),"-") -> 45544 | E19: - | G19: Attente R. | H19: Dossier à prioriser (Mail du 06/09) - BAT VT envoyé le 22/07 BAT V1 envoyé le 11/09 Rien à faire | I19: FAUX
A20: JU | B20: Novi - Chateauroux | C20: 45540.513 | D20: =IFERROR(_xlfn.WORKDAY.INTL(C20, 2),"-") -> 45544 | E20: - | G20: Attente R. | H20: BAT VT envoyé le 10/07 Photoshop bug... BAT V1 envoyé le 13/09 BAT v2 envoyé le 21/10 Rien à faire | I20: FAUX
A21: JU | B21: Novi - Dinan | C21: 45540.513 | D21: =IFERROR(_xlfn.WORKDAY.INTL(C21, 2),"-") -> 45544 | E21: - | G21: Attente R. | H21: BAT VT envoyé le 11/07 BAT VT n°2 envoyé le 11/09 BAT VT 2 reçu le 18/09 BAT v1 envoyé le 18/09 BAT v2 envoyé le 21/10 Rien à faire | I21: FAUX
A22: JU | B22: Novi - Bassens | C22: 45540.509 | D22: =IFERROR(_xlfn.WORKDAY.INTL(C22, 2),"-") -> 45544 | E22: - | G22: Attente R. | H22: BAT VT envoyé le 18/07 BAT v1 envoyé le 9/10 Rien à faire | I22: FAUX
A23: JU | B23: Novi - Lyon Charité | C23: 45554.631 | D23: =IFERROR(_xlfn.WORKDAY.INTL(C23, 2),"-") -> 45558 | E23: - | G23: Attente R. | H23: BAT VT fait par Jordan le 11/09 BAT v1 envoyé le 23/09 Rien à faire - projet archivé sur FP jsp pq | I23: FAUX
A24: JU | B24: Novi - Lyon Vitton | C24: 45554.507 | D24: =IFERROR(_xlfn.WORKDAY.INTL(C24, 2),"-") -> 45558 | E24: - | G24: Attente R. | H24: BAT VT fait par Jordan le 11/10 BAT v1 envoyé le 23/09 Rien à faire - projet archivé sur FP jsp pq | I24: FAUX
A25: JU | B25: Novi Lyon Neuve | C25: 45554.507 | D25: =IFERROR(_xlfn.WORKDAY.INTL(C25, 2),"-") -> 45558 | E25: - | G25: Attente R. | H25: BAT VT fait par Jordan le 11/11 BAT v1 envoyé le 23/09 Rien à faire - projet archivé sur FP jsp pq | I25: FAUX
A26: JU | B26: Novi - Cournon D'auvergne | C26: 45540.513 | D26: =IFERROR(_xlfn.WORKDAY.INTL(C26, 2),"-") -> 45544 | E26: - | G26: Attente R. | H26: BAT VT envoyé le 11/07 BAT v1 envoyé le 17/09 BAT v2 envoyé le 19/12 Rien à faire | I26: FAUX
A27: JU | B27: Novi - Cran Gevrier | C27: 45540.51 | D27: =IFERROR(_xlfn.WORKDAY.INTL(C27, 2),"-") -> 45544 | E27: - | G27: Attente R. | H27: BAT VT envoyé le 22/07 BAT v1 envoyé le 9/10 Rien à faire | I27: FAUX
A28: JU | B28: Novi - Annecy Prefecture | C28: 45540.509 | D28: =IFERROR(_xlfn.WORKDAY.INTL(C28, 2),"-") -> 45544 | E28: - | G28: Attente R. | H28: BAT VT envoyé le 18/07 BAT V1 envoyé le 25/09 Rien à faire | I28: FAUX
A29: JU | B29: Novi - Bruz | C29: 45540 | D29: 45574 | E29: - | G29: Attente R. | H29: BAT VT envoyé le 10/07 Besoin photo supplémentaire, demande envoyé le 12/09 BAT v1 envoyé le 28/11 BAT V2 envoyé le 29/11 Rien à faire
A30: JU | B30: Synagogue Villeurbanne | C30: 45985.598 | G30: Attente R. | H30: BAT envoyé le 24/11 Attente retour - Rien à faire | I30: FAUX
A31: JU | B31: CO2502-3448 - MR ENSEIGNES - SMASH BRO | C31: 45985.649 | E31: F | G31: Attente R. | H31: BAT V1 - 06/05 BAT V2 - 28/05 BAT Mairie - 07/03 Refus Mairie - 01/10 Attente retour client.
A32: JU | B32: efdd92cb - NOVI PUGET-SUR-ARGENS | C32: 45985.649 | D32: =IFERROR(_xlfn.WORKDAY.INTL(C32, 2),"-") -> 45987 | E32: M | G32: Attente R. | H32: BAT VT - 22/07 BAT V1 Franchise - 06/11 Relance - 06/02 - 17/04 - 28/05 Demande arrêt des relances de Marie-Odile - 17/04 Attente validation BAT | I32: FAUX
A33: JU | B33: ad0458e5 - NOVI EVREUX ✅ | C33: 45978.406 | D33: =IFERROR(_xlfn.WORKDAY.INTL(C33, 2),"-") -> 45980 | E33: M | G33: Attente R. | H33: BAT VT - 10/07 BAT V1 Franchise - 16/09 BAT V2 Franchise - 22/10 Relance - 06/02 - 17/04 - 28/05 Demande arrêt des relances de Marie-Odile - 17/04 Attente validation BAT | I33: FAUX
A34: JU | B34: Lobby Guys | C34: 45985.609 | G34: Attente R. | H34: BAT v1 envoyé le 16/12 Attente retour - Rien à faire | I34: FAUX
A35: JU | B35: Brenntag SA | C35: 45999.517 | G35: Attente R. | H35: BAT à faire mais pas de visuel dans le brief > relancer Michael pour avoir le visuel (le lien sur FP marche pas) BAT le 8/12 Attente retour - rien à faire | I35: FAUX
A36: JU | B36: GH NANTES | C36: 45943.393 | G36: Mairie | H36: BAT V1 le 25/02 BAT v2 le 12/03 BAT v3 le 18/03 VAT v4 le 31/03 BAT v5 le 8/04 BAT franchise le 8/04 Mairie + retour mairie BAT le 13/10 et relance le 14/10 BAT v6 renvoyé suite retour franchise le 16/10 > attente validation Rein à faire | I36: FAUX
A37: JU | B37: GUY HOQUET Saint Pierre La Mer | C37: 45701.443 | D37: =IFERROR(_xlfn.WORKDAY.INTL(C37, 2),"-") -> 45705 | E37: - | G37: Mairie | H37: En attente validation, relancé le 13/02 BAT mairie le 17/04 enlever les coffrage BAT renvoyé le 25/08 suite retour mairie BAT mairie fait le 21/09 - rien à faire | I37: FAUX
A38: JU | B38: CO2506-3919_1 - RENOVERT - AIX EN PROVENCE | C38: 45985.646 | G38: Mairie | H38: BAT V1 - 24/07 BAT V2 - 29/07 BAT V3 - 01/08 BAT V4 - 04/08 BAT V5 - 08/08 BAT V6 - 15/09 BAT V7 - 18/09 BAT V8 - 06/10 BAT partie 1 validé, fabriqué et posé BAT partie 2 attente validation mairie | I38: FAUX
A39: JU | B39: Juri Gestion | C39: 45939.409 | G39: Stand-by | H39: BAT (mise en page) à faire + appel client BAT envoyé le 15/10 Retour reçu le 15/10 Carte de visite et ppage de garde envoyé mais attente d'envoie de coordonée pour lancer la prod des carte de visits | I39: FAUX
A40: JU | B40: Beelodge - Atelier 80 | C40: 45831.447 | G40: Stand-by | H40: BAT VT à faire suivant photos de Zoé ( en attente de We trasnfer) BAT v1 envoyé le 21/08 Projet en Attente de Beelodge (ils sont souvent très long à valider le BAT et le devis) | I40: FAUX
...

Sheet LAURIE
A1: LAURIE
B2: DOSSIER : | C2: DATE RAJOUT | D2: DDL. 1ERE REPONSE | E2: COM. | F2: DDL. COM. | G2: STATUT | H2: COMMENTAIRES : | I2: DOSSIER TERMINÉ :
A3: L
A4: L | C4: - | D4: =IFERROR(_xlfn.WORKDAY.INTL(C4, 2),"-") -> - | E4: - | I4: FAUX
A5: L | E5: - | I5: FAUX
A6: L | E6: - | I6: FAUX
A7: L | E7: - | I7: FAUX
A8: L | C8: - | D8: =IFERROR(_xlfn.WORKDAY.INTL(C8, 2),"-") -> - | E8: - | I8: FAUX
A9: L | C9: - | D9: =IFERROR(_xlfn.WORKDAY.INTL(C9, 2),"-") -> - | E9: - | I9: FAUX
A10: L | C10: - | D10: =IFERROR(_xlfn.WORKDAY.INTL(C10, 2),"-") -> - | E10: - | I10: FAUX
A11: L | C11: - | D11: =IFERROR(_xlfn.WORKDAY.INTL(C11, 2),"-") -> - | E11: - | I11: FAUX
A12: L | C12: - | D12: =IFERROR(_xlfn.WORKDAY.INTL(C12, 2),"-") -> - | E12: - | I12: FAUX
A13: L | C13: - | D13: =IFERROR(_xlfn.WORKDAY.INTL(C13, 2),"-") -> - | E13: - | I13: FAUX
A14: L | C14: - | D14: =IFERROR(_xlfn.WORKDAY.INTL(C14, 2),"-") -> - | E14: - | I14: FAUX
A15: L | C15: - | D15: =IFERROR(_xlfn.WORKDAY.INTL(C15, 2),"-") -> - | E15: - | I15: FAUX
A16: L | C16: - | D16: =IFERROR(_xlfn.WORKDAY.INTL(C16, 2),"-") -> - | E16: - | I16: FAUX
A17: L | C17: - | D17: =IFERROR(_xlfn.WORKDAY.INTL(C17, 2),"-") -> - | E17: - | I17: FAUX
A18: L | C18: - | D18: =IFERROR(_xlfn.WORKDAY.INTL(C18, 2),"-") -> - | E18: - | I18: FAUX
A19: L | C19: - | D19: =IFERROR(_xlfn.WORKDAY.INTL(C19, 2),"-") -> - | E19: - | I19: FAUX
... A88: L | C88: - | D88: =IFERROR(_xlfn.WORKDAY.INTL(C88, 2),"-") -> - | E88: - | I88: FAUX
A89: L
A90: L | I90: FAUX
A91: L | I91: FAUX
A92: L | I92: FAUX
A93: L | I93: FAUX
A94: L | I94: FAUX
A95: L | I95: FAUX
A96: L | I96: FAUX
A97: L | I97: FAUX
A98: L | I98: FAUX
A99: L | I99: FAUX
A100: L | I100: FAUX
A101: L | I101: FAUX
... A1088: L | I1088: FAUX

Sheet GUILLAUME
A1: GUILLAUME
B2: DOSSIER : | C2: DATE RAJOUT | D2: DDL. 1ERE REPONSE | E2: COM. | F2: DDL. COM. | G2: STATUT | H2: COMMENTAIRES : | I2: DOSSIER TERMINÉ :
A4: G
A5: G
A6: G
A7: G
A8: G
A9: G
A10: G
A11: G
A12: G
A13: G
A15: G | C15: - | D15: =IFERROR(_xlfn.WORKDAY.INTL(C15, 2),"-") -> - | E15: - | I15: FAUX
A16: G | C16: - | D16: =IFERROR(_xlfn.WORKDAY.INTL(C16, 2),"-") -> - | E16: - | I16: FAUX
A17: G | C17: - | D17: =IFERROR(_xlfn.WORKDAY.INTL(C17, 2),"-") -> - | E17: - | I17: FAUX
A18: G | C18: - | D18: =IFERROR(_xlfn.WORKDAY.INTL(C18, 2),"-") -> - | E18: - | I18: FAUX
A19: G | C19: - | D19: =IFERROR(_xlfn.WORKDAY.INTL(C19, 2),"-") -> - | E19: - | I19: FAUX
A20: G | C20: - | D20: =IFERROR(_xlfn.WORKDAY.INTL(C20, 2),"-") -> - | E20: - | I20: FAUX
A21: G | C21: - | D21: =IFERROR(_xlfn.WORKDAY.INTL(C21, 2),"-") -> - | E21: - | I21: FAUX
A22: G | C22: - | D22: =IFERROR(_xlfn.WORKDAY.INTL(C22, 2),"-") -> - | E22: - | I22: FAUX
A23: G | C23: - | D23: =IFERROR(_xlfn.WORKDAY.INTL(C23, 2),"-") -> - | E23: - | I23: FAUX
A24: G | C24: - | D24: =IFERROR(_xlfn.WORKDAY.INTL(C24, 2),"-") -> - | E24: - | I24: FAUX
A25: G | C25: - | D25: =IFERROR(_xlfn.WORKDAY.INTL(C25, 2),"-") -> - | E25: - | I25: FAUX
A26: G | C26: - | D26: =IFERROR(_xlfn.WORKDAY.INTL(C26, 2),"-") -> - | E26: - | I26: FAUX
... A370: G | C370: - | D370: =IFERROR(_xlfn.WORKDAY.INTL(C370, 2),"-") -> - | E370: - | I370: FAUX
A371: G

Sheet MARION
A1: MARION
B2: DOSSIER : | C2: DATE RAJOUT | D2: DDL. 1ERE REPONSE | E2: COM. | F2: DDL. COM. | G2: STATUT | H2: COMMENTAIRES : | I2: DOSSIER TERMINÉ :
A3: Ar
A4: Ar
A5: Ar
A6: Ar
A7: Ar
A8: Ar
A9: Ar
A10: Ar
A11: Ar
A12: Ar
A13: Ar
A14: Ar
... A16: Ar
A17: Ar | C17: - | D17: =IFERROR(_xlfn.WORKDAY.INTL(C17, 2),"-") -> - | I17: FAUX
A18: Ar | C18: - | D18: =IFERROR(_xlfn.WORKDAY.INTL(C18, 2),"-") -> - | I18: FAUX
A19: Ar | C19: - | D19: =IFERROR(_xlfn.WORKDAY.INTL(C19, 2),"-") -> - | I19: FAUX
A20: Ar | C20: - | D20: =IFERROR(_xlfn.WORKDAY.INTL(C20, 2),"-") -> - | I20: FAUX
A21: Ar | C21: - | D21: =IFERROR(_xlfn.WORKDAY.INTL(C21, 2),"-") -> - | I21: FAUX
A22: Ar | C22: - | D22: =IFERROR(_xlfn.WORKDAY.INTL(C22, 2),"-") -> - | I22: FAUX
A23: Ar | C23: - | D23: =IFERROR(_xlfn.WORKDAY.INTL(C23, 2),"-") -> - | I23: FAUX
A24: Ar | C24: - | D24: =IFERROR(_xlfn.WORKDAY.INTL(C24, 2),"-") -> - | I24: FAUX
A25: Ar | C25: - | D25: =IFERROR(_xlfn.WORKDAY.INTL(C25, 2),"-") -> - | I25: FAUX
A26: Ar | C26: - | D26: =IFERROR(_xlfn.WORKDAY.INTL(C26, 2),"-") -> - | I26: FAUX
A27: Ar | C27: - | D27: =IFERROR(_xlfn.WORKDAY.INTL(C27, 2),"-") -> - | I27: FAUX
A28: Ar | C28: - | D28: =IFERROR(_xlfn.WORKDAY.INTL(C28, 2),"-") -> - | I28: FAUX
... A558: Ar | C558: - | D558: =IFERROR(_xlfn.WORKDAY.INTL(C558, 2),"-") -> - | I558: FAUX

Sheet QUENTIN
A1: QUENTIN | I1: ( Ctrl + Alt + Shit + 1 )
B2: DOSSIER : | C2: DATE RAJOUT | D2: DDL. 1ERE REPONSE | E2: COM. | F2: DDL. COM. | G2: STATUT | H2: COMMENTAIRES : | I2: DOSSIER TERMINÉ :
A3: Q | B3: Guy Hoquet Villenave d'Ornon | C3: 46002.656 | D3: =IFERROR(_xlfn.WORKDAY.INTL(C3, 2),"-") -> 46006 | E3: - | G3: Attente R. | H3: 11/12 - En attente validation client | I3: FAUX
A4: Q | B4: CO2511-4594 - Guy Hoquet Marcq en Baroeul | C4: 46002.703 | D4: =IFERROR(_xlfn.WORKDAY.INTL(C4, 2),"-") -> 46006 | E4: - | G4: Attente R. | H4: 16/12 - En attente validation Franchiseur | I4: FAUX
A5: Q | B5: CO2512-4742 -SARL CGN - Affiche | C5: 46006.686 | D5: =IFERROR(_xlfn.WORKDAY.INTL(C5, 2),"-") -> 46008 | E5: - | G5: En cours | H5: 17/12 - En attente éléments Michael // 17/12 - En attente validation client // 19/12 - Modifications | I5: FAUX
A6: Q | B6: CO2512-4739 - Panneaux plexi | C6: 46006.686 | D6: =IFERROR(_xlfn.WORKDAY.INTL(C6, 2),"-") -> 46008 | E6: - | G6: Attente R. | H6: 17/12 - En attente validation client // 17/12 - BAT refusé // 17/12 - En attente validation client | I6: FAUX
A7: Q | B7: CO2512-4734 - SARL CGN - Création charte graphique | C7: 46001.421 | D7: =IFERROR(_xlfn.WORKDAY.INTL(C7, 2),"-") -> 46003 | E7: - | G7: En cours | H7: 16/12 - Brief pris auprès du client // 17/12 - Créa en cours // 18/12 - Propositions logo envoyées // 19/12 - modififcations suivant les directives client | I7: FAUX
A8: Q | B8: CO2512-4719_3 - Guy Hoquet Saint-Denis | C8: 46007.671 | D8: =IFERROR(_xlfn.WORKDAY.INTL(C8, 2),"-") -> 46009 | E8: - | G8: Attente R. | H8: 18/12 - BAT envoyé Franchiseur // 19/12 - BAT VT déposée sur FP | I8: FAUX
A9: Q | C9: - | D9: =IFERROR(_xlfn.WORKDAY.INTL(C9, 2),"-") -> - | E9: - | I9: FAUX
A10: Q | C10: - | D10: =IFERROR(_xlfn.WORKDAY.INTL(C10, 2),"-") -> - | E10: - | I10: FAUX
A11: Q | C11: - | D11: =IFERROR(_xlfn.WORKDAY.INTL(C11, 2),"-") -> - | E11: - | I11: FAUX
A12: Q | C12: - | D12: =IFERROR(_xlfn.WORKDAY.INTL(C12, 2),"-") -> - | E12: - | I12: FAUX
A13: Q | C13: - | D13: =IFERROR(_xlfn.WORKDAY.INTL(C13, 2),"-") -> - | E13: - | I13: FAUX
A14: Q | C14: - | D14: =IFERROR(_xlfn.WORKDAY.INTL(C14, 2),"-") -> - | E14: - | I14: FAUX
A15: Q | C15: - | D15: =IFERROR(_xlfn.WORKDAY.INTL(C15, 2),"-") -> - | E15: - | I15: FAUX
A16: Q | C16: - | D16: =IFERROR(_xlfn.WORKDAY.INTL(C16, 2),"-") -> - | E16: - | I16: FAUX
A17: Q | C17: - | D17: =IFERROR(_xlfn.WORKDAY.INTL(C17, 2),"-") -> - | E17: - | I17: FAUX
A18: Q | C18: - | D18: =IFERROR(_xlfn.WORKDAY.INTL(C18, 2),"-") -> - | E18: - | I18: FAUX
A19: Q | C19: - | D19: =IFERROR(_xlfn.WORKDAY.INTL(C19, 2),"-") -> - | E19: - | I19: FAUX
A20: Q | C20: - | D20: =IFERROR(_xlfn.WORKDAY.INTL(C20, 2),"-") -> - | E20: - | I20: FAUX
... A911: Q | C911: - | D911: =IFERROR(_xlfn.WORKDAY.INTL(C911, 2),"-") -> - | E911: - | I911: FAUX
A912: Q

Sheet ARCHIVE
A1: ARCHIVE DOSSIERS TERMINES
A3: C | B3: RIA FR8089 | C3: 46001.741 | G3: Attente R. | H3: BAT 1 envoyé le 10-12 BAT validé - attente VT et validation devis | I3: VRAI
A4: C | B4: Association Buers | C4: 46002.604 | G4: Attente R. | H4: BAT 1 envoyé le 16-12 BAT 2 envoyé le 19-12 | I4: VRAI
A5: C | B5: SQ Bruges Verdun interieur | C5: 45957.508 | G5: Attente R. | H5: Attente de brief Relance le 11-12 BAT 1 envoyé le 16-12 BAT 2 envoyé le 17-12 | I5: VRAI
A6: J | B6: GDS Tassin - Devanture | C6: 45978.351 | D6: =IFERROR(_xlfn.WORKDAY.INTL(C6, 2),"-") -> 45980 | E6: - | G6: Attente R. | H6: BAT V1 envoyé le 17/11 à Sophie-Amélie - Modif à faire - V2 envoyé le 18/11 - V3 le 18/11 - V4 le 19/11 - Relance le 24/11 - Ok franchiseur le 17/12 - Envoie au franchisé le 17/12 | I6: VRAI
A7: C | B7: RIA FR17124 | C7: 45988.728 | G7: Attente R. | H7: BAT 1 envoyé le 3-12 BAT VT fait le 3-12 Relance le 4-12 BAT 2 envoyé le4-12 BAT 3 envoyé le 5-12 BAT ET DEVIS validé - attente VT | I7: VRAI
A8: J | B8: Edra Michinot | C8: 46003.406 | D8: =IFERROR(_xlfn.WORKDAY.INTL(C8, 2),"-") -> 46007 | E8: - | G8: Attente R. | H8: BAT V1 envoyé le 16/12 | I8: VRAI
A9: J | B9: Mr Enseignes - The First Light | C9: 46008.365 | D9: =IFERROR(_xlfn.WORKDAY.INTL(C9, 2),"-") -> 46010 | E9: - | G9: Attente R. | H9: BAT V1 envoyé le 17/12 - V2 le 18/12 | I9: VRAI
A10: J | B10: Temporis Nantes Santé | C10: 46006.591 | D10: =IFERROR(_xlfn.WORKDAY.INTL(C10, 2),"-") -> 46008 | E10: - | G10: Attente R. | H10: BAT V1 envoyé le 15/12 - V2 le 18/12 | I10: VRAI
A11: J | B11: Piscine Ibiza - SAS Brodeac signalétique extérieur + marquage véhicule | C11: 45985.52 | D11: =IFERROR(_xlfn.WORKDAY.INTL(C11, 2),"-") -> 45987 | E11: - | G11: A faire | H11: V1 envoyé le 08/12 à Amanda pour les nouveaux véhicules - V2 envoyé le 10/12 - Nouvelles plaquettes validées - V1 BAT global envoyé le 11/12 - BAT Validé côté franchiseur, BAT envoyé au franchisé le 15/12 - BAT V2 envoyé le 17/12 - V3 le 17/12 - FAB A FAIRE | I11: VRAI
A12: Q | B12: CO2512-4738 - My Little Invest - Marquage véhicule | C12: 46002.524 | D12: =IFERROR(_xlfn.WORKDAY.INTL(C12, 2),"-") -> 46006 | E12: - | G12: En cours | H12: 11/12 - En attente Visuel Vitres arrière // 15/12 - Créa BAT // 15/12 - En attente validation client // 17/12 - Modif BAT // 17/12 - En attente validation client | I12: VRAI
A13: J | B13: EDRA Carrosserie Ayvazian | C13: 46006.663 | D13: =IFERROR(_xlfn.WORKDAY.INTL(C13, 2),"-") -> 46008 | E13: - | G13: Attente R. | H13: BAT V1 envoyé le 16/12 | I13: VRAI
A14: J | B14: Temporis - Toulouse Ouest | C14: 46001.567 | D14: =IFERROR(_xlfn.WORKDAY.INTL(C14, 2),"-") -> 46003 | E14: - | G14: Attente R. | H14: BAT V1 envoyé le 15/12 | I14: VRAI
A15: J | B15: Librairie BlackSpell | C15: 45919.463 | D15: =IFERROR(_xlfn.WORKDAY.INTL(C15, 2),"-") -> 45923 | E15: - | G15: A faire | H15: 27/08 BAT V1 - 01/09 BAT V2 + BAT mairie - FAB A FAIRE | I15: VRAI
A16: C | B16: vallois Bureau détudes | C16: 46008.422 | G16: Attente R. | H16: Reprise dossier Marie BAT modifié renvoyé à Avner et Léa - attente validation BAT 2 envoyé le17-12 | I16: VRAI
A17: J | B17: Modification du site "Sourire d'enfant" | C17: 46008.431 | D17: =IFERROR(_xlfn.WORKDAY.INTL(C17, 2),"-") -> 46010 | E17: - | G17: Attente R. | H17: V1 des modifs faites, mail le 17/12 pour demander de nouvel envoi des photos + précisions sur certains points | I17: VRAI
A18: JU | B18: Generasons | C18: 45999.518 | G18: A faire | H18: BAT à faire | I18: VRAI
A19: JU | B19: Aragor | C19: 45999.518 | G19: A faire | H19: BAT à faire | I19: VRAI
A20: JU | B20: Pyramide Online | C20: 45999.516 | G20: Attente R. | H20: BAT à faire mais incompréhension sur les fichiers transmis et la demande > voir avec Avner BAT envoyé le 8/12 Attente retour - rien à faire | I20: VRAI
A21: JU | B21: See&be | C21: 45929.37 | G21: Mairie | H21: BAT validé le 1/10 BAT mairie le 1/10 Rien à faire | I21: VRAI
A22: JU | B22: GH Carpentras | G22: Mairie | H22: BAT envoyé le 6/10 à la franchise BAT valiidée par la franchise - renvoyé au franchisé le 20/10 BAT mairie le 19/11 Rien à faire | I22: VRAI
A23: JU | B23: Hydro Buiding Technal | C23: 45985.596 | G23: Attente R. | H23: BAT v1 envoyé le 24/11 Attente retour - Rien à faire | I23: VRAI
A24: JU | B24: GH Lyon 7 | C24: 45779.455 | G24: Attente R. | H24: ATtente photo VT ( client relancé 3fois) VAT VT le 9/06 BAT le 11/06 BAT v2 envoyé le 24/06 BAT v3 le 25/06 Projet e stand-y attente d'accord entres la franchise et le franchisé (manque de budget pour avoir les éléments de la charte) Retour de Pauline > c'est une demande de la copro d'avoir que des adhésif alors c'est ok donc attente de MAureen pour valider mon BAT BAT validé par la franchise le 24/11 BAT envoyé le 4/12 FAB le 6/12 | I24: VRAI
A25: C | B25: SQ Suresnes adh prix | C25: 46007.626 | G25: Attente R. | H25: BAT 1 envoyé le 16-12 | I25: VRAI
A26: C | B26: SQ La Rochelle interieur | C26: 45936.432 | G26: Attente R. | H26: En attente de brief BAT 1 envoyé le 11-12 BAT 2 envoyé le 16-12 | I26: VRAI
A27: C | B27: Euronet topper 200H | C27: 46006.683 | G27: Attente R. | H27: BAT 1 envoyé le 15-12 | I27: VRAI
A28: C | B28: SQ Bretteville exterieur | C28: 45943.388 | G28: Mairie | H28: BAT VT fait le 13-10 BAT 1 envoyé le 13-10 BAT 2 envoyé le 23-10 BAT 3 envoyé le 3-11 BAT 4 envoyé le 5-11 BAT 5 envoyé le 19-11 BAT mairie fait le 20-11 | I28: VRAI
A29: J | B29: Edra MV Automobiles | C29: 45981.447 | D29: =IFERROR(_xlfn.WORKDAY.INTL(C29, 2),"-") -> 45985 | E29: - | G29: Attente R. | H29: BAT V1 envoyé le 24/11 - V2 le 15/12 - FAB A FAIRE | I29: VRAI
A30: C | B30: SQ Gennevillier adh | C30: 46002.604 | G30: Attente R. | H30: BAT 1 envoyé le 11-12 BAT 2 envoyé le 12-12 | I30: VRAI
A31: C | B31: RIA FR16574 | C31: 45988.728 | G31: Attente R. | H31: BAT 1 envoyé le 3-12 BAT VT fait le 3-12 Relance le 4-12 BAT 2 envoyé le 4-12 BAT et devis validé - attente VT | I31: VRAI
A32: C | B32: Alliance française Lyon | C32: 45966.683 | G32: Attente R. | H32: BAT 1 envoyé le 18-11 BAT 2 envoyé le 21-11 BAT 3 envoyé le 4-12 BAT 4 envoyé le 5-12 Relance le 8-12 BAT 5 envoyé le 11-12 | I32: VRAI
A33: J | B33: EDRA Avignon Carrosserie Auto Doral | C33: 46001.37 | D33: =IFERROR(_xlfn.WORKDAY.INTL(C33, 2),"-") -> 46003 | E33: - | G33: Attente R. | H33: BAT V1 envoyé le 11/12 | I33: VRAI
A34: J | B34: EDRA La Madeleine Soc Exploitation Garage Michel Dubois | C34: 46001.37 | D34: =IFERROR(_xlfn.WORKDAY.INTL(C34, 2),"-") -> 46003 | E34: - | G34: Attente R. | H34: BAT V1 envoyé le 11/12 | I34: VRAI
A35: J | B35: EDRA Villepinte | C35: 46001.567 | D35: =IFERROR(_xlfn.WORKDAY.INTL(C35, 2),"-") -> 46003 | E35: - | G35: Attente R. | H35: BAT V1 envoyé le 11/12 | I35: VRAI
A36: Q | B36: Panneau copro | C36: 46001.415 | D36: =IFERROR(_xlfn.WORKDAY.INTL(C36, 2),"-") -> 46003 | E36: - | G36: - | H36: Panneau ENTREE et panneau SORTIE 500*300mm fond blanc texte noir Panneau sens interdit diamètre 400mm | I36: VRAI
A37: C | B37: LPA Paradis du fruit | C37: 45981.832 | G37: Attente R. | H37: BAT VT fait le 28-11 BAT 1 envoyé le 8-12 BAT 2 envoyé le 10-12 à Oriane BAT 3 envoyé le 10-12 | I37: VRAI
A38: C | B38: Topadev | C38: 46001.379 | G38: Attente R. | H38: BAT 1 envoyé le 10-12 | I38: VRAI
A39: J | B39: EDRA - Saint Maurice de Beynost BF System | C39: 45995.644 | D39: =IFERROR(_xlfn.WORKDAY.INTL(C39, 2),"-") -> 45999 | E39: - | G39: Attente R. | H39: BAT V1 envoyé le 09/12 - V2 le 09/12 | I39: VRAI
A40: J | B40: EDRA - Carats Automobiles | C40: 46000.451 | D40: =IFERROR(_xlfn.WORKDAY.INTL(C40, 2),"-") -> 46002 | E40: - | G40: Attente R. | H40: BAT V1 envoyé le 09/12 - V2 le 09/12 | I40: VRAI
A41: C | B41: RIA FR16448 | C41: 45995.641 | G41: Attente R. | H41: BAT VT fait le 11-09 BAT 1 envoyé le 29-10 BAT 2 envoyé le 31-10 BAT 3 envoyé le 3-12 BAT 4 envoyé le 3-12 Relance le 4-12 BAT 5 envoyé le 4-12 BAT 1 envoyé le 26-06 BAT 2 envoyé le 27-06 BAT 3 envoyé le 30-06 Relance le 30-06 Relance le 16-07 Relance le 30-07 Relance le 20-08 Relance le 29-08 Relance le 5-09 Relance le 2-10 Ria demande une VT - BAT VT fait le 9-10 BAT 4 envoyé le 22-10 BAT 5 envoyé le 12-11 Relance le 4-12 BAT 6 envoyé le 4-12 BAT validé- attente validation devis | I41: VRAI
...

Sheet LUCIE
A1: LUCIE
B2: DOSSIER : | C2: DATE RAJOUT | D2: DDL. 1ERE REPONSE | E2: COM. | F2: DDL. COM. | G2: STATUT | H2: COMMENTAIRES : | I2: DOSSIER TERMINÉ :
A3: L | C3: - | D3: =IFERROR(_xlfn.WORKDAY.INTL(C3, 2),"-") -> - | I3: FAUX
A4: L | C4: - | D4: =IFERROR(_xlfn.WORKDAY.INTL(C4, 2),"-") -> - | I4: FAUX
A5: L | C5: - | D5: =IFERROR(_xlfn.WORKDAY.INTL(C5, 2),"-") -> - | I5: FAUX
A6: L | C6: - | D6: =IFERROR(_xlfn.WORKDAY.INTL(C6, 2),"-") -> - | I6: FAUX
A7: L | C7: - | D7: =IFERROR(_xlfn.WORKDAY.INTL(C7, 2),"-") -> - | I7: FAUX
A8: L | C8: - | D8: =IFERROR(_xlfn.WORKDAY.INTL(C8, 2),"-") -> - | I8: FAUX
A9: L | C9: - | D9: =IFERROR(_xlfn.WORKDAY.INTL(C9, 2),"-") -> - | I9: FAUX
A10: L | C10: - | D10: =IFERROR(_xlfn.WORKDAY.INTL(C10, 2),"-") -> - | I10: FAUX
A11: L | C11: - | D11: =IFERROR(_xlfn.WORKDAY.INTL(C11, 2),"-") -> - | I11: FAUX
A12: L | C12: - | D12: =IFERROR(_xlfn.WORKDAY.INTL(C12, 2),"-") -> - | I12: FAUX
A13: L | C13: - | D13: =IFERROR(_xlfn.WORKDAY.INTL(C13, 2),"-") -> - | I13: FAUX
A14: L | C14: - | D14: =IFERROR(_xlfn.WORKDAY.INTL(C14, 2),"-") -> - | I14: FAUX
... A712: L | C712: - | D712: =IFERROR(_xlfn.WORKDAY.INTL(C712, 2),"-") -> - | I712: FAUX

Sheet MODELE_NG
A1: LUCIE
B2: DOSSIER : | C2: DATE RAJOUT | D2: DDL. 1ERE REPONSE | E2: COM. | F2: DDL. COM. | G2: STATUT | H2: COMMENTAIRES : | I2: DOSSIER TERMINÉ :
A3: A | C3: - | D3: =IFERROR(_xlfn.WORKDAY.INTL(C3, 2),"-") -> - | I3: FAUX
A4: A | C4: - | D4: =IFERROR(_xlfn.WORKDAY.INTL(C4, 2),"-") -> - | I4: FAUX
A5: A | C5: - | D5: =IFERROR(_xlfn.WORKDAY.INTL(C5, 2),"-") -> - | I5: FAUX
A6: A | C6: - | D6: =IFERROR(_xlfn.WORKDAY.INTL(C6, 2),"-") -> - | I6: FAUX
A7: A | C7: - | D7: =IFERROR(_xlfn.WORKDAY.INTL(C7, 2),"-") -> - | I7: FAUX
A8: A | C8: - | D8: =IFERROR(_xlfn.WORKDAY.INTL(C8, 2),"-") -> - | I8: FAUX
A9: A | C9: - | D9: =IFERROR(_xlfn.WORKDAY.INTL(C9, 2),"-") -> - | I9: FAUX
A10: A | C10: - | D10: =IFERROR(_xlfn.WORKDAY.INTL(C10, 2),"-") -> - | I10: FAUX
A11: A | C11: - | D11: =IFERROR(_xlfn.WORKDAY.INTL(C11, 2),"-") -> - | I11: FAUX
A12: A | C12: - | D12: =IFERROR(_xlfn.WORKDAY.INTL(C12, 2),"-") -> - | I12: FAUX
A13: A | C13: - | D13: =IFERROR(_xlfn.WORKDAY.INTL(C13, 2),"-") -> - | I13: FAUX
A14: A | C14: - | D14: =IFERROR(_xlfn.WORKDAY.INTL(C14, 2),"-") -> - | I14: FAUX
... A738: A | C738: - | D738: =IFERROR(_xlfn.WORKDAY.INTL(C738, 2),"-") -> - | I738: FAUX

Sheet PAUL
A1: PAUL
B2: DOSSIER : | C2: DATE RAJOUT | D2: DDL. 1ERE REPONSE | E2: COM. | F2: DDL. COM. | G2: STATUT | H2: COMMENTAIRES : | I2: DOSSIER TERMINÉ :
A3: P | C3: - | D3: =IFERROR(_xlfn.WORKDAY.INTL(C3, 2),"-") -> - | I3: FAUX
A4: P | C4: - | D4: =IFERROR(_xlfn.WORKDAY.INTL(C4, 2),"-") -> - | I4: FAUX
A5: P | C5: - | D5: =IFERROR(_xlfn.WORKDAY.INTL(C5, 2),"-") -> - | I5: FAUX
A6: P | C6: - | D6: =IFERROR(_xlfn.WORKDAY.INTL(C6, 2),"-") -> - | I6: FAUX
A7: P | C7: - | D7: =IFERROR(_xlfn.WORKDAY.INTL(C7, 2),"-") -> - | I7: FAUX
A8: P | C8: - | D8: =IFERROR(_xlfn.WORKDAY.INTL(C8, 2),"-") -> - | I8: FAUX
A9: P | C9: - | D9: =IFERROR(_xlfn.WORKDAY.INTL(C9, 2),"-") -> - | I9: FAUX
A10: P | C10: - | D10: =IFERROR(_xlfn.WORKDAY.INTL(C10, 2),"-") -> - | I10: FAUX
A11: P | C11: - | D11: =IFERROR(_xlfn.WORKDAY.INTL(C11, 2),"-") -> - | I11: FAUX
A12: P | C12: - | D12: =IFERROR(_xlfn.WORKDAY.INTL(C12, 2),"-") -> - | I12: FAUX
A13: P | C13: - | D13: =IFERROR(_xlfn.WORKDAY.INTL(C13, 2),"-") -> - | I13: FAUX
A14: P | C14: - | D14: =IFERROR(_xlfn.WORKDAY.INTL(C14, 2),"-") -> - | I14: FAUX
... A713: P | C713: - | D713: =IFERROR(_xlfn.WORKDAY.INTL(C713, 2),"-") -> - | I713: FAUX

Sheet FRANK
A1: FRANK
B2: DOSSIER : | C2: DATE RAJOUT | D2: DDL. 1ERE REPONSE | E2: COM. | F2: DDL. COM. | G2: STATUT | H2: DOSIER | I2: NUMERO | J2: COMMENTAIRES : | K2: DOSSIER TERMINÉ :
A3: F | C3: - | D3: =IFERROR(_xlfn.WORKDAY.INTL(C3, 2),"-") -> - | K3: FAUX
A4: F | C4: - | D4: =IFERROR(_xlfn.WORKDAY.INTL(C4, 2),"-") -> - | K4: FAUX
A5: F | C5: - | D5: =IFERROR(_xlfn.WORKDAY.INTL(C5, 2),"-") -> - | K5: FAUX
A6: F | C6: - | D6: =IFERROR(_xlfn.WORKDAY.INTL(C6, 2),"-") -> - | K6: FAUX
A7: F | C7: - | D7: =IFERROR(_xlfn.WORKDAY.INTL(C7, 2),"-") -> - | K7: FAUX
A8: F | C8: - | D8: =IFERROR(_xlfn.WORKDAY.INTL(C8, 2),"-") -> - | K8: FAUX
A9: F | C9: - | D9: =IFERROR(_xlfn.WORKDAY.INTL(C9, 2),"-") -> - | K9: FAUX
A10: F | C10: - | D10: =IFERROR(_xlfn.WORKDAY.INTL(C10, 2),"-") -> - | K10: FAUX
A11: F | C11: - | D11: =IFERROR(_xlfn.WORKDAY.INTL(C11, 2),"-") -> - | K11: FAUX
A12: F | C12: - | D12: =IFERROR(_xlfn.WORKDAY.INTL(C12, 2),"-") -> - | K12: FAUX
A13: F | C13: - | D13: =IFERROR(_xlfn.WORKDAY.INTL(C13, 2),"-") -> - | K13: FAUX
A14: F | C14: - | D14: =IFERROR(_xlfn.WORKDAY.INTL(C14, 2),"-") -> - | K14: FAUX
... A692: F | C692: - | D692: =IFERROR(_xlfn.WORKDAY.INTL(C692, 2),"-") -> - | K692: FAUX

Sheet STATS_2025
A3: Jordan | B3: =COUNTA(JORDAN!B3:B21) -> 41 | J3: =SUM(L3+K3) -> 342 | K3: =COUNTIF(ARCHIVE!A1:Y1522,"J") -> 342 | R3: =SUM(B3+J3) -> 383
A4: Hugo | B4: =COUNTA(HUGO!B3:B21) -> 0 | J4: =SUM(L8+K4) -> 5 | K4: =COUNTIF(ARCHIVE!A1:A1522,"H") -> 5 | R4: =SUM(B4+J4) -> 5
A5: Carole | B5: =COUNTA(CAROLE!B3:B21) -> 60 | J5: =SUM(L13+K5) -> 493 | K5: =COUNTIF(ARCHIVE!A1:A1522,"C") -> 493 | R5: =SUM(B5+J5) -> 553
A6: Marie | B6: =COUNTA(MARIE!B3:B21) -> 0 | J6: =SUM(L15+K6) -> 126 | K6: =COUNTIF(ARCHIVE!A1:A1522,"Ma") -> 126 | R6: =SUM(B6+J6) -> 126
A7: Juliette | B7: =COUNTA(JULIETTE!B3:B21) -> 45 | J7: =SUM(L16+K7) -> 241 | K7: =COUNTIF(ARCHIVE!A1:A1522,"JU") -> 241 | R7: =SUM(B7+J7) -> 286
A8: Lucie | B8: =COUNTA(LUCIE!B3:B21) -> 0 | J8: =SUM(L17+K8) -> 17 | K8: =COUNTIF(ARCHIVE!A1:A1523,"L") -> 17 | R8: =SUM(B8+J8) -> 17
A9: Paul | B9: =COUNTA(PAUL!B3:B21) -> 0 | J9: =SUM(L18+K9) -> 19 | K9: =COUNTIF(ARCHIVE!A1:A1524,"P") -> 19 | R9: =SUM(B9+J9) -> 19
A10: Marion | B10: =COUNTA(MARION!B3:B21) -> 0 | J10: =SUM(L19+K10) -> 164 | K10: =COUNTIF(ARCHIVE!A1:A1525,"Ar") -> 164 | R10: =SUM(B10+J10) -> 164
A11: Frank | B11: =COUNTA(FRANK!B3:B21) -> 0 | J11: =SUM(L20+K11) -> 24 | K11: =COUNTIF(ARCHIVE!A1:A1526,"F") -> 24 | R11: =SUM(B11+J11) -> 24
A12: Quentin | B12: =COUNTA(QUENTIN!B3:B21) -> 6 | J12: =SUM(L7+K12) -> 2 | K12: =COUNTIF(ARCHIVE!A1:A1522,"Q") -> 2 | R12: =SUM(B12+J12) -> 8
B21: =TODAY() -> 46013 | C21: 45658 | D21: Nbr de jours ouvrés pris en compte : | F21: =NETWORKDAYS(C21, B21,) -> 254 | K21: Total de dossiers : | M21: =SUM(R:R) -> 1585

Sheet STATS_2024
A3: Jordan | B3: =COUNTA(JORDAN!B3:B21) -> 41 | J3: =SUM(L3+K3) -> 676 | K3: =COUNTIF(ARCHIVE!A1:A3179,"J") -> 676 | R3: =SUM(B3+J3) -> 717
A8: Hugo | B8: =COUNTA(HUGO!B3:B21) -> 0 | J8: =SUM(L8+K8) -> 232 | K8: =COUNTIF(ARCHIVE!A1:A3179,"H") -> 232 | R8: =SUM(B8+J8) -> 232
A9: Guillaume | B9: =COUNTA(GUILLAUME!B3:B21) -> 0 | J9: =SUM(L9+K9) -> 0 | K9: =COUNTIF(ARCHIVE!A1:A3179,"G") -> 0 | R9: =SUM(B9+J9) -> 0
J10: =SUM(L10+K10) -> 0 | K10: =COUNTIF(ARCHIVE!A1:A3179,"JB") -> 0 | R10: =SUM(B10+J10) -> 0
A11: Laurie | B11: =COUNTA(LAURIE!B3:B21) -> 0 | J11: =SUM(L11+K11) -> 79 | K11: =COUNTIF(ARCHIVE!A1:A3179,"L") -> 79 | R11: =SUM(B11+J11) -> 79
A12: Vanessa | B12: 0 | J12: =SUM(L12+K12) -> 50 | K12: =COUNTIF(ARCHIVE!A1:A3179,"V") -> 50 | R12: =SUM(B12+J12) -> 50
A13: Carole | B13: =COUNTA(CAROLE!B3:B21) -> 60 | J13: =SUM(L13+K13) -> 1091 | K13: =COUNTIF(ARCHIVE!A1:A3179,"C") -> 1091 | R13: =SUM(B13+J13) -> 1151
A14: Audrey | B14: =COUNTA(AUDREY!B3:B21) -> 15 | J14: =SUM(L14+K14) -> 242 | K14: =COUNTIF(ARCHIVE!A1:A3179,"A") -> 242 | R14: =SUM(B14+J14) -> 257
A15: Marie | B15: =COUNTA(MARIE!B3:B21) -> 0 | J15: =SUM(L15+K15) -> 154 | K15: =COUNTIF(ARCHIVE!A1:A3179,"Ma") -> 154 | R15: =SUM(B15+J15) -> 154
A16: Juliette | B16: =COUNTA(JULIETTE!B3:B21) -> 45 | J16: =SUM(L16+K16) -> 313 | K16: =COUNTIF(ARCHIVE!A1:A3179,"JU") -> 313 | R16: =SUM(B16+J16) -> 358
B21: 45658 | C21: 45300 | D21: Nbr de jours ouvrés pris en compte : | F21: =NETWORKDAYS(C21, B21,) -> 257 | K21: Total de dossiers : | M21: =SUM(R:R) -> 2998

Sheet FRANCHISES
B2: ATTRIBUTION DES FRANCHISES :
B3: FRANCHISES | C3: Jordan | D3: Carole | E3: Juliette
B4: Anacours | C4: FALSE | D4: FALSE | E4: TRUE
B5: Bagelstein | C5: FALSE | D5: FALSE | E5: TRUE
B6: Bureau Vallée | C6: FALSE | D6: FALSE | E6: FALSE
B7: Camif Habitat | C7: TRUE | D7: FALSE | E7: FALSE
B8: General des Services | C8: TRUE | D8: FALSE | E8: FALSE
B9: La Main Tendue | C9: FALSE | D9: FALSE | E9: FALSE
B10: Lady Sushi | C10: FALSE | D10: TRUE | E10: FALSE
B11: Point Code | C11: FALSE | D11: FALSE | E11: TRUE
B12: Viva Services | C12: FALSE | D12: TRUE | E12: FALSE
B13: Ria | C13: FALSE | D13: TRUE | E13: FALSE
B14: Temporis | C14: TRUE | D14: FALSE | E14: FALSE
B15: Brenntag | C15: FALSE | D15: TRUE | E15: FALSE
... B43: Destia | C43: TRUE | D43: FALSE | E43: FALSE
C44: FALSE | D44: FALSE | E44: FALSE
C45: FALSE | D45: FALSE | E45: FALSE
C46: FALSE | D46: FALSE | E46: FALSE
C47: FALSE | D47: FALSE | E47: FALSE

Sheet JB
A1: JB
B2: DOSSIER : | C2: DATE RAJOUT | D2: DDL. 1ERE REPONSE | E2: COM. | F2: DDL. COM. | G2: STATUT | H2: COMMENTAIRES : | I2: DOSSIER TERMINÉ :
A3: JB | C3: - | D3: =IFERROR(_xlfn.WORKDAY.INTL(C3, 2),"-") -> - | E3: - | I3: FAUX
A4: JB | C4: - | D4: =IFERROR(_xlfn.WORKDAY.INTL(C4, 2),"-") -> - | E4: - | I4: FAUX
A5: JB | C5: - | D5: =IFERROR(_xlfn.WORKDAY.INTL(C5, 2),"-") -> - | E5: - | I5: FAUX
A6: JB | C6: - | D6: =IFERROR(_xlfn.WORKDAY.INTL(C6, 2),"-") -> - | E6: - | I6: FAUX
A7: JB | C7: - | D7: =IFERROR(_xlfn.WORKDAY.INTL(C7, 2),"-") -> - | E7: - | I7: FAUX
A8: JB | C8: - | D8: =IFERROR(_xlfn.WORKDAY.INTL(C8, 2),"-") -> - | E8: - | I8: FAUX
A9: JB | C9: - | D9: =IFERROR(_xlfn.WORKDAY.INTL(C9, 2),"-") -> - | E9: - | I9: FAUX
A10: JB | C10: - | D10: =IFERROR(_xlfn.WORKDAY.INTL(C10, 2),"-") -> - | E10: - | I10: FAUX
A11: JB | C11: - | D11: =IFERROR(_xlfn.WORKDAY.INTL(C11, 2),"-") -> - | E11: - | I11: FAUX
A12: JB | C12: - | D12: =IFERROR(_xlfn.WORKDAY.INTL(C12, 2),"-") -> - | E12: - | I12: FAUX
A13: JB | C13: - | D13: =IFERROR(_xlfn.WORKDAY.INTL(C13, 2),"-") -> - | E13: - | I13: FAUX
A14: JB | C14: - | D14: =IFERROR(_xlfn.WORKDAY.INTL(C14, 2),"-") -> - | E14: - | I14: FAUX
... A278: JB | C278: - | D278: =IFERROR(_xlfn.WORKDAY.INTL(C278, 2),"-") -> - | E278: - | I278: FAUX
A279: JB

Sheet MICKAEL
A1: MICKAEL
B2: DOSSIER : | C2: DATE RAJOUT | D2: DDL. 1ERE REPONSE | E2: COM. | F2: DDL. COM. | G2: STATUT | H2: COMMENTAIRES : | I2: DOSSIER TERMINÉ :
A3: M | B3: Dentinov - Republique | C3: 44817.5 | D3: - | E3: M | G3: A faire | H3: BAT envoyé 08/09 / VT OK / Adhésifs uniquement retour client 08/09 : "c’est trop opaque, il ne faut pas recouvrir la totalité de la vitre " Réduire hauteur Dépoli Insister pour avoir un plan intérieur des cloisons. BAT RETOUR 14/09 | I3: FAUX
A4: M | B4: Mr Medical | C4: 44817.494 | D4: - | E4: M | G4: A faire | H4: BAT envoyé 22/06/22 → Demande nouvelle proposition → Attente de brief M.Kessous → En attente de rappel et relance mail 06/07/2022 Nouvelle relance 15/07/22 Nouvelle relance 14/09/22 | I4: FAUX
A5: M | B5: Dentinov / Villeurbanne - ZOLA | C5: 44817.502 | D5: - | E5: M | G5: A faire | H5: BAT RE- envoyé 29/08 / VT ok - RELANCE 13/09 | I5: FAUX
A6: M | C6: - | D6: =IFERROR(_xlfn.WORKDAY.INTL(C6, 2),"-") -> - | E6: - | I6: FAUX
A7: M | C7: - | D7: =IFERROR(_xlfn.WORKDAY.INTL(C7, 2),"-") -> - | E7: - | I7: FAUX
A8: M | C8: - | D8: =IFERROR(_xlfn.WORKDAY.INTL(C8, 2),"-") -> - | E8: - | I8: FAUX
A9: M | C9: - | D9: =IFERROR(_xlfn.WORKDAY.INTL(C9, 2),"-") -> - | E9: - | I9: FAUX
A10: M | C10: - | D10: =IFERROR(_xlfn.WORKDAY.INTL(C10, 2),"-") -> - | E10: - | I10: FAUX
A11: M | C11: - | D11: =IFERROR(_xlfn.WORKDAY.INTL(C11, 2),"-") -> - | E11: - | I11: FAUX
A12: M | C12: - | D12: =IFERROR(_xlfn.WORKDAY.INTL(C12, 2),"-") -> - | E12: - | I12: FAUX
A13: M | C13: - | D13: =IFERROR(_xlfn.WORKDAY.INTL(C13, 2),"-") -> - | E13: - | I13: FAUX
A14: M | C14: - | D14: =IFERROR(_xlfn.WORKDAY.INTL(C14, 2),"-") -> - | E14: - | I14: FAUX
A15: M | C15: - | D15: =IFERROR(_xlfn.WORKDAY.INTL(C15, 2),"-") -> - | E15: - | I15: FAUX
A16: M | C16: - | D16: =IFERROR(_xlfn.WORKDAY.INTL(C16, 2),"-") -> - | E16: - | I16: FAUX
A17: M | C17: - | D17: =IFERROR(_xlfn.WORKDAY.INTL(C17, 2),"-") -> - | E17: - | I17: FAUX
... A826: M | C826: - | D826: =IFERROR(_xlfn.WORKDAY.INTL(C826, 2),"-") -> - | E826: - | I826: FAUX
A827: M

Sheet DAVID
A1: DAVID
B2: DOSSIER : | C2: DATE RAJOUT | D2: DDL. 1ERE REPONSE | E2: COM. | F2: DDL. COM. | G2: STATUT | H2: COMMENTAIRES : | I2: DOSSIER TERMINÉ :
A3: D | C3: - | D3: =IFERROR(_xlfn.WORKDAY.INTL(C3, 2),"-") -> - | E3: - | I3: FAUX
A4: D | C4: - | D4: =IFERROR(_xlfn.WORKDAY.INTL(C4, 2),"-") -> - | E4: - | I4: FAUX
A5: D | C5: - | D5: =IFERROR(_xlfn.WORKDAY.INTL(C5, 2),"-") -> - | E5: - | I5: FAUX
A6: D | C6: - | D6: =IFERROR(_xlfn.WORKDAY.INTL(C6, 2),"-") -> - | E6: - | I6: FAUX
A7: D | C7: - | D7: =IFERROR(_xlfn.WORKDAY.INTL(C7, 2),"-") -> - | E7: - | I7: FAUX
A8: D | C8: - | D8: =IFERROR(_xlfn.WORKDAY.INTL(C8, 2),"-") -> - | E8: - | I8: FAUX
A9: D | C9: - | D9: =IFERROR(_xlfn.WORKDAY.INTL(C9, 2),"-") -> - | E9: - | I9: FAUX
A10: D | C10: - | D10: =IFERROR(_xlfn.WORKDAY.INTL(C10, 2),"-") -> - | E10: - | I10: FAUX
A11: D | C11: - | D11: =IFERROR(_xlfn.WORKDAY.INTL(C11, 2),"-") -> - | E11: - | I11: FAUX
A12: D | C12: - | D12: =IFERROR(_xlfn.WORKDAY.INTL(C12, 2),"-") -> - | E12: - | I12: FAUX
A13: D | C13: - | D13: =IFERROR(_xlfn.WORKDAY.INTL(C13, 2),"-") -> - | E13: - | I13: FAUX
A14: D | C14: - | D14: =IFERROR(_xlfn.WORKDAY.INTL(C14, 2),"-") -> - | E14: - | I14: FAUX
... A833: D | C833: - | D833: =IFERROR(_xlfn.WORKDAY.INTL(C833, 2),"-") -> - | E833: - | I833: FAUX
A834: D

Sheet TEST
E8: Nbr de BAT envoyé
F9: 1

Sheet STATS_2023
A1: 264
A3: Jordan | B3: 0 | J3: =SUM(L3+K3) -> 493 | K3: =COUNTIF(ARCHIVE!A3179:A4517,"J") -> 493 | R3: =SUM(B3+J3) -> 493
A8: Hugo | B8: 0 | J8: =SUM(L8+K8) -> 305 | K8: =COUNTIF(ARCHIVE!A3179:A4517,"H") -> 305 | R8: =SUM(B8+J8) -> 305
A9: Guillaume | B9: 0 | J9: =SUM(L9+K9) -> 207 | K9: =COUNTIF(ARCHIVE!A3179:A4517,"G") -> 207 | R9: =SUM(B9+J9) -> 207
A10: JB | B10: 0 | J10: =SUM(L10+K10) -> 37 | K10: =COUNTIF(ARCHIVE!A3179:A4517,"JB") -> 37 | R10: =SUM(B10+J10) -> 37
A11: Laurie | B11: 0 | J11: =SUM(L11+K11) -> 102 | K11: =COUNTIF(ARCHIVE!A3179:A4518,"L") -> 102 | R11: =SUM(B11+J11) -> 102
A12: Vanessa | B12: 0 | J12: =SUM(L12+K12) -> 26 | K12: =COUNTIF(ARCHIVE!A3179:A4518,"V") -> 26 | R12: =SUM(B12+J12) -> 26
A13: Carole | B13: 0 | J13: =SUM(L13+K13) -> 134 | K13: =COUNTIF(ARCHIVE!A3179:A4518,"C") -> 134 | R13: =SUM(B13+J13) -> 134
B21: 45300 | C21: 44931 | D21: Nbr de jours ouvrés pris en compte : | F21: =NETWORKDAYS(C21, B21,) -> 264 | K21: Total de dossiers : | M21: =SUM(R:R) -> 1304

Sheet STATS_2022
A3: Jordan | B3: 0 | J3: =SUM(L3+K3) -> 573 | K3: =COUNTIF(ARCHIVE!A21:A4286,"J") -> 392 | L3: =COUNTIF(ARCHIVE!D:D,"Jordan") -> 181 | R3: =SUM(B3+J3) -> 573
A4: David | B4: 0 | J4: =SUM(L4+K4) -> 185 | K4: =COUNTIF(ARCHIVE!A21:A4286,"D") -> 103 | L4: =COUNTIF(ARCHIVE!D:D,"David") -> 82 | R4: =SUM(B4+J4) -> 185
A5: Carole | B5: 0 | J5: =SUM(L5+K5) -> 208 | K5: =COUNTIF(ARCHIVE!A21:A4286,"C") -> 79 | L5: =COUNTIF(ARCHIVE!D:D,"Carole") -> 129 | R5: =SUM(B5+J5) -> 208
A6: Quentin | B6: 0 | J6: =SUM(L6+K6) -> 37 | K6: =COUNTIF(ARCHIVE!A21:A4286,"Q") -> 33 | L6: =COUNTIF(ARCHIVE!D:D,"Quentin") -> 4 | R6: =SUM(B6+J6) -> 37
A7: Mickael | B7: 0 | J7: =SUM(L7+K7) -> 21 | K7: =COUNTIF(ARCHIVE!A:A,"M") -> 21 | R7: =SUM(B7+J7) -> 21
A8: Hugo | B8: 0 | J8: =SUM(L8+K8) -> 99 | K8: =COUNTIF(ARCHIVE!A21:A4286,"H") -> 99 | R8: =SUM(B8+J8) -> 99
A9: Guillaume | B9: 0 | J9: =SUM(L9+K9) -> 52 | K9: =COUNTIF(ARCHIVE!A21:A4286,"G") -> 52 | R9: =SUM(B9+J9) -> 52
B21: 45001 | C21: 44580 | D21: Nbr de jours ouvrés pris en compte : | F21: =NETWORKDAYS(C21, B21,) -> 302 | K21: Total de dossiers : | M21: =SUM(R:R) -> 1175

Sheet PROJETS_INTERNE
B2: Commercial | C2: Tâche | D2: Demande | E2: Graphiste | F2: Terminé
B3: Michael | C3: Process atelier | D3: Mise en forme des process / contraintes atelier. Fiche à destination des graphistes pour réalisation des fichiers de fabrication | E3: Carole | F3: FALSE
B4: Michael | C4: Catalogue "Les Enseignistes" | D4: Mise à jour du gros catalogue "JMJCOM" en rebrand "Les Enseignistes", corrections d'erreur, réalisation de simulation 3D, changement de photos etc | F4: FALSE
B5: Michael | C5: Modification des BAT | D5: Créer un modèle de BAT "cochable", afin que tous les graphistes indique systématiquement la même chose dans le BAT - Brief avec Michael avant | E5: Carole | F5: FALSE
B6: Antoine | C6: Page produits | D6: Réalisation d'une page (A4) pour expliquer chaque produit, exemple une fiche dépoli, expliquant le produit, avec des photos d'exemples, les avantages, les inconvénients, les spécificité techniques (exemple "Imprimable : Oui / Non") etc | F6: TRUE
B7: Michael | C7: Showroom | D7: Showroom de base pour franchise "Les Enseignistes" | E7: Jordan | F7: TRUE
B8: Michael | C8: Vidéo formation | D8: Tournage et montage des vidéos destinées à la formation de poseurs en fonction d'un document pré-établi | F8: FALSE
B9: Michael | C9: Post sur le personnel | D9: Réalisation d'un post "Interview" sur les RS de "Les Enseignistes" sur le personnel de la société | F9: FALSE
B10: Michael | C10: Mockup | D10: Création et préparation de Mockup de qualité (pour la réalisation de nos BAT) donc des mockup généraliste avec les produits que l'on réalise régulièrement | F10: FALSE
B11: Michael | C11: Newsletter | D11: Création de Newsletter pour Les Enseignistes / Work & Progress / Mr Enseignes | F11: FALSE
B12: Michael | C12: Vidéo écran | D12: Création de vidéo pour les écrans d'affichage en interne - Brief avec Michael pour savoir les informations à y mettre | F12: TRUE
B13: Marie / Michael | D13: Afichage RSE | F13: FALSE
B14: Michael | D14: Brochure franchisé (modèle) | F14: FALSE
B15: Michael | D15: Vidéo devenez franchisé | F15: FALSE
F16: FALSE
F17: FALSE
F18: FALSE
F19: FALSE
F20: FALSE
F21: FALSE
F22: FALSE
F23: FALSE
F24: FALSE
F25: FALSE
F26: FALSE
F27: FALSE
... F1000: FALSE

Sheet MARIE
B2: DOSSIER : | C2: DATE RAJOUT | D2: DDL. 1ERE REPONSE | E2: COM. | F2: DDL. COM. | G2: STATUT | H2: COMMENTAIRES : | I2: DOSSIER TERMINÉ :
I3: FAUX
I4: FAUX
I5: FAUX
I6: FAUX
I7: FAUX
I8: FAUX
I9: FAUX
I10: FAUX
I11: FAUX
I12: FAUX
I13: FAUX
I14: FAUX
... I985: FAUX

Sheet Feuille 5
A1: [WEB] Netilav | B1: Réalisation logo [OK] + développement site internet en cours
A2: Bureau Vallée - St Malo | B2: Attente retour client (Travaux sur la facade finissant fin Juin)
A3: Towers Location | B3: Modif envoyée le 29/04
A4: Profire | B4: 7 Véhicules à faire (Différents) → FAB 4/7 (2BAT + 1 demande d'info en cours le 07/04) + Relance le 02/05
A5: Netilav | B5: Modif à faire puis lancement en FAB
A6: SQ - Site | B6: Refonte charte --> Refaire image et dimension des produits
A7: JMJCOM | B7: Analyse de capacité nécessaire + recherche disque dur sauvegarde froide
A8: Guy Hoquet Panneaux | B8: Relance téléphonique à Eva (06 34 41 00 43) le 07/03
A9: GDS Angouleme | B9: MODIF BAT envoyé le 28/04
A10: JMJCOM | B10: Protection des mots de passe en les mettant dans un logiciel tiers
A11: LyonCab | B11: Paramétrage DNS
A12: JMJCOM | B12: Organisation, achat et déploiement modem Wifi
... A39: JMJCOM | B39: Signalétique "Bâche à l'envers" → RECRUTE POSEURS SIGNALETIQUE (Logo + Tel + Site) 4000x1200mm
